Workbook

Sheet README
A1: Grid de experimentos del Radar
A3: Basado en el esquema del archivo subido: Funcion_Perdida_Radar_y_Grid_Experimentos.docx
A5: Cómo usar este archivo
A6: 1) En 'RESULTADOS_GRID', cada fila representa un resultado por horizonte (1, 2, 3 o 4 semanas) para un run.
A7: 2) Completa métricas de entrada: L_num, L_trend, L_risk, L_tol, MAE, RMSE, dirección accuracy y detección de caídas.
A8: 3) Los pesos alpha, beta, gamma, delta y w_h se traen automáticamente desde 'CONFIG_REFERENCIA'.
A9: 4) En 'RUN_SUMMARY' se consolida el score multi-horizonte por Run_ID y se calcula L_total_Radar = Σ Loss_h + eta × L_coh.
A10: 5) Usa 'CATALOGO_EXPERIMENTOS' como plantilla base (E1–E10) y duplica o añade runs según vayas probando variantes.
A12: Notas
A13: 6) Cierre oficial E1 Ridge: E1_v5_clean queda como mejor Ridge limpio global y E1_v4_clean como referencia parsimoniosa.
A14: 7) Cierre oficial E2 Huber: E2_v3_clean gana internamente, E2_v2_clean descarta convergencia como causa principal y la familia queda cerrada.
A15: 8) E2_v4_clean queda cancelada por decision metodologica explicita y no se ejecuta.
... A21: Morado = control / lógica

Sheet CONFIG_REFERENCIA
A1: Pesos por horizonte | D1: Pesos internos de la pérdida | G1: Catálogos / listas | O1: Formula de referencia
A2: Horizonte_sem | B2: Peso_w | D2: Parametro | E2: Valor | G2: Familia | H2: Target | I2: Transformacion | J2: Seleccion_variables | K2: Validacion | L2: Estado | M2: Decision | O2: Loss_h = w_h × (alpha×L_num + beta×L_trend + gamma×L_risk + delta×L_tol)
A3: 1 | B3: 0.3 | D3: alpha | E3: 0.35 | G3: lineal | H3: nivel | I3: original | J3: todas | K3: walk-forward | L3: pendiente | M3: descartar | O3: L_total_Radar = Σ Loss_h + eta × L_coh
A4: 2 | B4: 0.25 | D4: beta | E4: 0.25 | G4: robusto | H4: delta | I4: estandarizada | J4: correlacion | K4: expanding_window | L4: correr | M4: contender
A5: 3 | B5: 0.3 | D5: gamma | E5: 0.25 | G5: boosting | H5: ambos | I5: log | J5: lasso | K5: rolling_window | L5: corrido | M5: finalista
A6: 4 | B6: 0.15 | D6: delta | E6: 0.1 | G6: temporal | I6: robusta | J6: importancia_arboles | L6: revisar | M6: ganador
D7: eta | E7: 0.05 | G7: hibrido | I7: winsorizada
G8: ensemble

Sheet CATALOGO_EXPERIMENTOS
A1: Experiment_ID | B1: Familia | C1: Modelo_base | D1: Objetivo | E1: Variables_base | F1: Validacion_recomendada | G1: Notas
A2: E1 | B2: lineal | C2: Ridge / Elastic Net | D2: Baseline interpretable por horizonte | E2: Lags del IAD + variables tematicas | F2: walk-forward | G2: Ridge cerrado como rama principal: E1_v5_clean mejor global por L_total_Radar; E1_v4_clean referencia parsimoniosa. No continuar automaticamente con E1_v6+.
A3: E2 | B3: robusto | C3: Huber Regressor | D3: Baseline robusto a ruido y outliers | E3: Lags del IAD + variables tematicas | F3: walk-forward | G3: Familia cerrada bajo esquema limpio temporal: E2_v3_clean gana internamente, E2_v2_clean descarta convergencia como explicacion principal y E2_v4_clean se cancela por decision metodologica. No competitiva frente a E1_v5_clean.
A4: E3 | B4: boosting | C4: Random Forest | D4: Explorar no linealidades básicas | E4: Variables temporales y tematicas | F4: walk-forward | G4: Siguiente prioridad operativa: Random Forest clean con el mismo marco temporal. Referencia principal E1_v5_clean; referencias secundarias E1_v4_clean y E2_v3_clean.
A5: E4 | B5: boosting | C5: XGBoost / LightGBM | D5: Candidato fuerte para tabular multi-factor | E5: Variables temporales y tematicas | F5: walk-forward | G5: Continuidad natural de E3: XGBoost / LightGBM con la misma arquitectura limpia por familias.
A6: E5 | B6: boosting | C6: CatBoost | D6: Comparar boosting con regularización | E6: Variables mixtas | F6: walk-forward | G6: Continuidad de boosting: CatBoost con el mismo marco temporal y comparaciones contra E1/E3.
A7: E6 | B7: temporal | C7: ARIMAX / SARIMAX | D7: Evaluar fuerza de la dinámica temporal | E7: Serie + regresores digitales | F7: walk-forward | G7: Capta bien tendencia/autocorrelación
A8: E7 | B8: temporal | C8: Prophet + regresores | D8: Alternativa temporal más flexible | E8: Serie + regresores | F8: walk-forward | G8: Útil como benchmark temporal flexible
A9: E8 | B9: hibrido | C9: Temporal + boosting residuales | D9: Captar tendencia base + shocks no lineales | E9: Temporal + tabular | F9: walk-forward | G9: Enfoque híbrido de alto potencial
A10: E9 | B10: hibrido | C10: Stacking lineal + boosting + temporal | D10: Combinar señales complementarias | E10: Modelos base complementarios | F10: walk-forward | G10: Conviene si hay ganadores distintos por horizonte
A11: E10 | B11: ensemble | C11: Mejor modelo por horizonte + ensemble final | D11: Maximizar desempeño operativo | E11: Ganadores por horizonte | F11: walk-forward | G11: Cierre natural del banco de modelos

Sheet RESULTADOS_GRID
A1: Fecha | B1: Run_ID | C1: Experiment_ID | D1: Familia_modelo | E1: Modelo | F1: Horizonte_sem | G1: Target | H1: Variables_temporales | I1: Variables_tematicas | J1: Transformacion | K1: Seleccion_variables | L1: Validacion | M1: Dataset_Periodo | N1: Notas_config | O1: alpha | P1: beta | Q1: gamma | R1: delta | S1: w_h | T1: L_num | U1: L_trend | V1: L_risk | W1: L_tol | X1: Loss_h | Y1: MAE | Z1: RMSE | AA1: Direccion_accuracy | AB1: Deteccion_caidas | AC1: Estado | AD1: Comentarios | AE1: Script_nombre | AF1: Script_ruta | AG1: Run_dir | AH1: Snapshot_script | AI1: Parametros_ruta_json | AJ1: Resultados_ruta_json | AK1: Timestamp_run | AL1: Task_type | AM1: Accuracy_5clases | AN1: Balanced_accuracy_5clases | AO1: Macro_f1_5clases | AP1: Weighted_f1_5clases | AQ1: Recall_baja_fuerte | AR1: Recall_baja_total | AS1: Precision_baja_fuerte | AT1: Recall_sube_fuerte | AU1: Recall_sube_total | AV1: Accuracy_3clases | AW1: Macro_f1_3clases | AX1: Balanced_accuracy_3clases | AY1: Loss_clasificacion_h
A2: 2026-03-21 06:37:15 | B2: E1_v1 | C2: E1 | D2: lineal | E2: RidgeCV | F2: 1 | G2: nivel | H2: y_t + lags 1..4 | I2: sentimiento_medios, v5_agua_neto, v5_alumbrado_neto, v5_americo_neto, v5_basura_neto, v5_corrupcion_neto, v5_delitos_neto, v5_morena_neto, v5_obras_neto, v5_prevencion_neto, v5_vialidad_neto | J2: estandarizada | K2: todas | L2: walk-forward_expanding | M2: 2024-10-14 a 2026-03-02 | N2: RidgeCV con 59 features, lags=[1, 2, 3, 4], initial_train_size=40 | O2: 0.35 | P2: 0.25 | Q2: 0.25 | R2: 0.1 | S2: 0.3 | T2: 0.17637742 | U2: 0.17857143 | V2: 0.23076923 | W2: 0.78571429 | X2: 0.072791607 | Y2: 0.10852222 | Z2: 0.13647812 | AA2: 0.82142857 | AB2: 0.76923077 | AC2: corrido | AD2: Retrointegrado desde metricas_horizonte.json para persistir resumen numerico. | AE2: run_e1_ridge.py | AF2: Scripts/Modeling/run_e1_ridge.py | AG2: Experimentos/runs/E1_v1_20260321_063715 | AH2: Experimentos/runs/E1_v1_20260321_063715/scripts/run_e1_ridge.py | AI2: Experimentos/runs/E1_v1_20260321_063715/parametros_run.json | AJ2: Experimentos/runs/E1_v1_20260321_063715/metricas_horizonte.json | AK2: 2026-03-21 06:37:15
A3: 2026-03-21 06:37:15 | B3: E1_v1 | C3: E1 | D3: lineal | E3: RidgeCV | F3: 2 | G3: nivel | H3: y_t + lags 1..4 | I3: sentimiento_medios, v5_agua_neto, v5_alumbrado_neto, v5_americo_neto, v5_basura_neto, v5_corrupcion_neto, v5_delitos_neto, v5_morena_neto, v5_obras_neto, v5_prevencion_neto, v5_vialidad_neto | J3: estandarizada | K3: todas | L3: walk-forward_expanding | M3: 2024-10-14 a 2026-03-02 | N3: RidgeCV con 59 features, lags=[1, 2, 3, 4], initial_train_size=40 | O3: 0.35 | P3: 0.25 | Q3: 0.25 | R3: 0.1 | S3: 0.25 | T3: 0.1677302 | U3: 0.40740741 | V3: 0.41666667 | W3: 0.77777778 | X3: 0.085625466 | Y3: 0.10320172 | Z3: 0.13166084 | AA3: 0.59259259 | AB3: 0.58333333 | AC3: corrido | AD3: Retrointegrado desde metricas_horizonte.json para persistir resumen numerico. | AE3: run_e1_ridge.py | AF3: Scripts/Modeling/run_e1_ridge.py | AG3: Experimentos/runs/E1_v1_20260321_063715 | AH3: Experimentos/runs/E1_v1_20260321_063715/scripts/run_e1_ridge.py | AI3: Experimentos/runs/E1_v1_20260321_063715/parametros_run.json | AJ3: Experimentos/runs/E1_v1_20260321_063715/metricas_horizonte.json | AK3: 2026-03-21 06:37:15
A4: 2026-03-21 06:37:15 | B4: E1_v1 | C4: E1 | D4: lineal | E4: RidgeCV | F4: 3 | G4: nivel | H4: y_t + lags 1..4 | I4: sentimiento_medios, v5_agua_neto, v5_alumbrado_neto, v5_americo_neto, v5_basura_neto, v5_corrupcion_neto, v5_delitos_neto, v5_morena_neto, v5_obras_neto, v5_prevencion_neto, v5_vialidad_neto | J4: estandarizada | K4: todas | L4: walk-forward_expanding | M4: 2024-10-14 a 2026-03-02 | N4: RidgeCV con 59 features, lags=[1, 2, 3, 4], initial_train_size=40 | O4: 0.35 | P4: 0.25 | Q4: 0.25 | R4: 0.1 | S4: 0.3 | T4: 0.17167648 | U4: 0.15384615 | V4: 0.16666667 | W4: 0.76923077 | X4: 0.065141415 | Y4: 0.1056298 | Z4: 0.13719619 | AA4: 0.84615385 | AB4: 0.83333333 | AC4: corrido | AD4: Retrointegrado desde metricas_horizonte.json para persistir resumen numerico. | AE4: run_e1_ridge.py | AF4: Scripts/Modeling/run_e1_ridge.py | AG4: Experimentos/runs/E1_v1_20260321_063715 | AH4: Experimentos/runs/E1_v1_20260321_063715/scripts/run_e1_ridge.py | AI4: Experimentos/runs/E1_v1_20260321_063715/parametros_run.json | AJ4: Experimentos/runs/E1_v1_20260321_063715/metricas_horizonte.json | AK4: 2026-03-21 06:37:15
A5: 2026-03-21 06:37:15 | B5: E1_v1 | C5: E1 | D5: lineal | E5: RidgeCV | F5: 4 | G5: nivel | H5: y_t + lags 1..4 | I5: sentimiento_medios, v5_agua_neto, v5_alumbrado_neto, v5_americo_neto, v5_basura_neto, v5_corrupcion_neto, v5_delitos_neto, v5_morena_neto, v5_obras_neto, v5_prevencion_neto, v5_vialidad_neto | J5: estandarizada | K5: todas | L5: walk-forward_expanding | M5: 2024-10-14 a 2026-03-02 | N5: RidgeCV con 59 features, lags=[1, 2, 3, 4], initial_train_size=40 | O5: 0.35 | P5: 0.25 | Q5: 0.25 | R5: 0.1 | S5: 0.15 | T5: 0.16576782 | U5: 0.28 | V5: 0.2 | W5: 0.72 | X5: 0.037502811 | Y5: 0.1019943 | Z5: 0.13564279 | AA5: 0.72 | AB5: 0.8 | AC5: corrido | AD5: Retrointegrado desde metricas_horizonte.json para persistir resumen numerico. | AE5: run_e1_ridge.py | AF5: Scripts/Modeling/run_e1_ridge.py | AG5: Experimentos/runs/E1_v1_20260321_063715 | AH5: Experimentos/runs/E1_v1_20260321_063715/scripts/run_e1_ridge.py | AI5: Experimentos/runs/E1_v1_20260321_063715/parametros_run.json | AJ5: Experimentos/runs/E1_v1_20260321_063715/metricas_horizonte.json | AK5: 2026-03-21 06:37:15
B6: E2_v1 | C6: E2 | D6: robusto | E6: Huber Regressor | F6: 1 | H6: lags IAD, MA, momentum | I6: indices tematicos / sentimiento | J6: robusta | K6: todas | L6: walk-forward | O6: =CONFIG_REFERENCIA!$E$3 | P6: =CONFIG_REFERENCIA!$E$4 | Q6: =CONFIG_REFERENCIA!$E$5 | R6: =CONFIG_REFERENCIA!$E$6 | S6: =IF($F6="","",INDEX(CONFIG_REFERENCIA!$B$3:$B$6,MATCH($F6,CONFIG_REFERENCIA!$A$3:$A$6,0))) | X6: =IF(COUNTA($T6:$W6)<4,"",$S6*($O6*$T6+$P6*$U6+$Q6*$V6+$R6*$W6)) | AC6: pendiente
B7: E2_v1 | C7: E2 | D7: robusto | E7: Huber Regressor | F7: 2 | H7: lags IAD, MA, momentum | I7: indices tematicos / sentimiento | J7: robusta | K7: todas | L7: walk-forward | O7: =CONFIG_REFERENCIA!$E$3 | P7: =CONFIG_REFERENCIA!$E$4 | Q7: =CONFIG_REFERENCIA!$E$5 | R7: =CONFIG_REFERENCIA!$E$6 | S7: =IF($F7="","",INDEX(CONFIG_REFERENCIA!$B$3:$B$6,MATCH($F7,CONFIG_REFERENCIA!$A$3:$A$6,0))) | X7: =IF(COUNTA($T7:$W7)<4,"",$S7*($O7*$T7+$P7*$U7+$Q7*$V7+$R7*$W7)) | AC7: pendiente
B8: E2_v1 | C8: E2 | D8: robusto | E8: Huber Regressor | F8: 3 | H8: lags IAD, MA, momentum | I8: indices tematicos / sentimiento | J8: robusta | K8: todas | L8: walk-forward | O8: =CONFIG_REFERENCIA!$E$3 | P8: =CONFIG_REFERENCIA!$E$4 | Q8: =CONFIG_REFERENCIA!$E$5 | R8: =CONFIG_REFERENCIA!$E$6 | S8: =IF($F8="","",INDEX(CONFIG_REFERENCIA!$B$3:$B$6,MATCH($F8,CONFIG_REFERENCIA!$A$3:$A$6,0))) | X8: =IF(COUNTA($T8:$W8)<4,"",$S8*($O8*$T8+$P8*$U8+$Q8*$V8+$R8*$W8)) | AC8: pendiente
B9: E2_v1 | C9: E2 | D9: robusto | E9: Huber Regressor | F9: 4 | H9: lags IAD, MA, momentum | I9: indices tematicos / sentimiento | J9: robusta | K9: todas | L9: walk-forward | O9: =CONFIG_REFERENCIA!$E$3 | P9: =CONFIG_REFERENCIA!$E$4 | Q9: =CONFIG_REFERENCIA!$E$5 | R9: =CONFIG_REFERENCIA!$E$6 | S9: =IF($F9="","",INDEX(CONFIG_REFERENCIA!$B$3:$B$6,MATCH($F9,CONFIG_REFERENCIA!$A$3:$A$6,0))) | X9: =IF(COUNTA($T9:$W9)<4,"",$S9*($O9*$T9+$P9*$U9+$Q9*$V9+$R9*$W9)) | AC9: pendiente
B10: E3_v1 | C10: E3 | D10: boosting | E10: Random Forest | F10: 1 | H10: lags, MA, volatilidad | I10: variables tematicas | J10: original | K10: importancia_arboles | L10: walk-forward | O10: =CONFIG_REFERENCIA!$E$3 | P10: =CONFIG_REFERENCIA!$E$4 | Q10: =CONFIG_REFERENCIA!$E$5 | R10: =CONFIG_REFERENCIA!$E$6 | S10: =IF($F10="","",INDEX(CONFIG_REFERENCIA!$B$3:$B$6,MATCH($F10,CONFIG_REFERENCIA!$A$3:$A$6,0))) | X10: =IF(COUNTA($T10:$W10)<4,"",$S10*($O10*$T10+$P10*$U10+$Q10*$V10+$R10*$W10)) | AC10: pendiente
B11: E3_v1 | C11: E3 | D11: boosting | E11: Random Forest | F11: 2 | H11: lags, MA, volatilidad | I11: variables tematicas | J11: original | K11: importancia_arboles | L11: walk-forward | O11: =CONFIG_REFERENCIA!$E$3 | P11: =CONFIG_REFERENCIA!$E$4 | Q11: =CONFIG_REFERENCIA!$E$5 | R11: =CONFIG_REFERENCIA!$E$6 | S11: =IF($F11="","",INDEX(CONFIG_REFERENCIA!$B$3:$B$6,MATCH($F11,CONFIG_REFERENCIA!$A$3:$A$6,0))) | X11: =IF(COUNTA($T11:$W11)<4,"",$S11*($O11*$T11+$P11*$U11+$Q11*$V11+$R11*$W11)) | AC11: pendiente
B12: E3_v1 | C12: E3 | D12: boosting | E12: Random Forest | F12: 3 | H12: lags, MA, volatilidad | I12: variables tematicas | J12: original | K12: importancia_arboles | L12: walk-forward | O12: =CONFIG_REFERENCIA!$E$3 | P12: =CONFIG_REFERENCIA!$E$4 | Q12: =CONFIG_REFERENCIA!$E$5 | R12: =CONFIG_REFERENCIA!$E$6 | S12: =IF($F12="","",INDEX(CONFIG_REFERENCIA!$B$3:$B$6,MATCH($F12,CONFIG_REFERENCIA!$A$3:$A$6,0))) | X12: =IF(COUNTA($T12:$W12)<4,"",$S12*($O12*$T12+$P12*$U12+$Q12*$V12+$R12*$W12)) | AC12: pendiente
B13: E3_v1 | C13: E3 | D13: boosting | E13: Random Forest | F13: 4 | H13: lags, MA, volatilidad | I13: variables tematicas | J13: original | K13: importancia_arboles | L13: walk-forward | O13: =CONFIG_REFERENCIA!$E$3 | P13: =CONFIG_REFERENCIA!$E$4 | Q13: =CONFIG_REFERENCIA!$E$5 | R13: =CONFIG_REFERENCIA!$E$6 | S13: =IF($F13="","",INDEX(CONFIG_REFERENCIA!$B$3:$B$6,MATCH($F13,CONFIG_REFERENCIA!$A$3:$A$6,0))) | X13: =IF(COUNTA($T13:$W13)<4,"",$S13*($O13*$T13+$P13*$U13+$Q13*$V13+$R13*$W13)) | AC13: pendiente
B14: E4_v1 | C14: E4 | D14: boosting | E14: XGBoost / LightGBM | F14: 1 | H14: lags, MA, volatilidad | I14: variables tematicas | J14: original | K14: importancia_arboles | L14: walk-forward | O14: =CONFIG_REFERENCIA!$E$3 | P14: =CONFIG_REFERENCIA!$E$4 | Q14: =CONFIG_REFERENCIA!$E$5 | R14: =CONFIG_REFERENCIA!$E$6 | S14: =IF($F14="","",INDEX(CONFIG_REFERENCIA!$B$3:$B$6,MATCH($F14,CONFIG_REFERENCIA!$A$3:$A$6,0))) | X14: =IF(COUNTA($T14:$W14)<4,"",$S14*($O14*$T14+$P14*$U14+$Q14*$V14+$R14*$W14)) | AC14: pendiente
B15: E4_v1 | C15: E4 | D15: boosting | E15: XGBoost / LightGBM | F15: 2 | H15: lags, MA, volatilidad | I15: variables tematicas | J15: original | K15: importancia_arboles | L15: walk-forward | O15: =CONFIG_REFERENCIA!$E$3 | P15: =CONFIG_REFERENCIA!$E$4 | Q15: =CONFIG_REFERENCIA!$E$5 | R15: =CONFIG_REFERENCIA!$E$6 | S15: =IF($F15="","",INDEX(CONFIG_REFERENCIA!$B$3:$B$6,MATCH($F15,CONFIG_REFERENCIA!$A$3:$A$6,0))) | X15: =IF(COUNTA($T15:$W15)<4,"",$S15*($O15*$T15+$P15*$U15+$Q15*$V15+$R15*$W15)) | AC15: pendiente
B16: E4_v1 | C16: E4 | D16: boosting | E16: XGBoost / LightGBM | F16: 3 | H16: lags, MA, volatilidad | I16: variables tematicas | J16: original | K16: importancia_arboles | L16: walk-forward | O16: =CONFIG_REFERENCIA!$E$3 | P16: =CONFIG_REFERENCIA!$E$4 | Q16: =CONFIG_REFERENCIA!$E$5 | R16: =CONFIG_REFERENCIA!$E$6 | S16: =IF($F16="","",INDEX(CONFIG_REFERENCIA!$B$3:$B$6,MATCH($F16,CONFIG_REFERENCIA!$A$3:$A$6,0))) | X16: =IF(COUNTA($T16:$W16)<4,"",$S16*($O16*$T16+$P16*$U16+$Q16*$V16+$R16*$W16)) | AC16: pendiente
B17: E4_v1 | C17: E4 | D17: boosting | E17: XGBoost / LightGBM | F17: 4 | H17: lags, MA, volatilidad | I17: variables tematicas | J17: original | K17: importancia_arboles | L17: walk-forward | O17: =CONFIG_REFERENCIA!$E$3 | P17: =CONFIG_REFERENCIA!$E$4 | Q17: =CONFIG_REFERENCIA!$E$5 | R17: =CONFIG_REFERENCIA!$E$6 | S17: =IF($F17="","",INDEX(CONFIG_REFERENCIA!$B$3:$B$6,MATCH($F17,CONFIG_REFERENCIA!$A$3:$A$6,0))) | X17: =IF(COUNTA($T17:$W17)<4,"",$S17*($O17*$T17+$P17*$U17+$Q17*$V17+$R17*$W17)) | AC17: pendiente
... B41: E10_v1 | C41: E10 | D41: ensemble | E41: Mejor modelo por horizonte + ensemble | F41: 4 | H41: ganadores por horizonte | I41: senales complementarias | J41: original | K41: todas | L41: walk-forward | O41: =CONFIG_REFERENCIA!$E$3 | P41: =CONFIG_REFERENCIA!$E$4 | Q41: =CONFIG_REFERENCIA!$E$5 | R41: =CONFIG_REFERENCIA!$E$6 | S41: =IF($F41="","",INDEX(CONFIG_REFERENCIA!$B$3:$B$6,MATCH($F41,CONFIG_REFERENCIA!$A$3:$A$6,0))) | X41: =IF(COUNTA($T41:$W41)<4,"",$S41*($O41*$T41+$P41*$U41+$Q41*$V41+$R41*$W41)) | AC41: pendiente
O42: =CONFIG_REFERENCIA!$E$3 | P42: =CONFIG_REFERENCIA!$E$4 | Q42: =CONFIG_REFERENCIA!$E$5 | R42: =CONFIG_REFERENCIA!$E$6 | S42: =IF($F42="","",INDEX(CONFIG_REFERENCIA!$B$3:$B$6,MATCH($F42,CONFIG_REFERENCIA!$A$3:$A$6,0))) | X42: =IF(COUNTA($T42:$W42)<4,"",$S42*($O42*$T42+$P42*$U42+$Q42*$V42+$R42*$W42))
O43: =CONFIG_REFERENCIA!$E$3 | P43: =CONFIG_REFERENCIA!$E$4 | Q43: =CONFIG_REFERENCIA!$E$5 | R43: =CONFIG_REFERENCIA!$E$6 | S43: =IF($F43="","",INDEX(CONFIG_REFERENCIA!$B$3:$B$6,MATCH($F43,CONFIG_REFERENCIA!$A$3:$A$6,0))) | X43: =IF(COUNTA($T43:$W43)<4,"",$S43*($O43*$T43+$P43*$U43+$Q43*$V43+$R43*$W43))
O44: =CONFIG_REFERENCIA!$E$3 | P44: =CONFIG_REFERENCIA!$E$4 | Q44: =CONFIG_REFERENCIA!$E$5 | R44: =CONFIG_REFERENCIA!$E$6 | S44: =IF($F44="","",INDEX(CONFIG_REFERENCIA!$B$3:$B$6,MATCH($F44,CONFIG_REFERENCIA!$A$3:$A$6,0))) | X44: =IF(COUNTA($T44:$W44)<4,"",$S44*($O44*$T44+$P44*$U44+$Q44*$V44+$R44*$W44))
O45: =CONFIG_REFERENCIA!$E$3 | P45: =CONFIG_REFERENCIA!$E$4 | Q45: =CONFIG_REFERENCIA!$E$5 | R45: =CONFIG_REFERENCIA!$E$6 | S45: =IF($F45="","",INDEX(CONFIG_REFERENCIA!$B$3:$B$6,MATCH($F45,CONFIG_REFERENCIA!$A$3:$A$6,0))) | X45: =IF(COUNTA($T45:$W45)<4,"",$S45*($O45*$T45+$P45*$U45+$Q45*$V45+$R45*$W45))
O46: =CONFIG_REFERENCIA!$E$3 | P46: =CONFIG_REFERENCIA!$E$4 | Q46: =CONFIG_REFERENCIA!$E$5 | R46: =CONFIG_REFERENCIA!$E$6 | S46: =IF($F46="","",INDEX(CONFIG_REFERENCIA!$B$3:$B$6,MATCH($F46,CONFIG_REFERENCIA!$A$3:$A$6,0))) | X46: =IF(COUNTA($T46:$W46)<4,"",$S46*($O46*$T46+$P46*$U46+$Q46*$V46+$R46*$W46))
O47: =CONFIG_REFERENCIA!$E$3 | P47: =CONFIG_REFERENCIA!$E$4 | Q47: =CONFIG_REFERENCIA!$E$5 | R47: =CONFIG_REFERENCIA!$E$6 | S47: =IF($F47="","",INDEX(CONFIG_REFERENCIA!$B$3:$B$6,MATCH($F47,CONFIG_REFERENCIA!$A$3:$A$6,0))) | X47: =IF(COUNTA($T47:$W47)<4,"",$S47*($O47*$T47+$P47*$U47+$Q47*$V47+$R47*$W47))
O48: =CONFIG_REFERENCIA!$E$3 | P48: =CONFIG_REFERENCIA!$E$4 | Q48: =CONFIG_REFERENCIA!$E$5 | R48: =CONFIG_REFERENCIA!$E$6 | S48: =IF($F48="","",INDEX(CONFIG_REFERENCIA!$B$3:$B$6,MATCH($F48,CONFIG_REFERENCIA!$A$3:$A$6,0))) | X48: =IF(COUNTA($T48:$W48)<4,"",$S48*($O48*$T48+$P48*$U48+$Q48*$V48+$R48*$W48))
O49: =CONFIG_REFERENCIA!$E$3 | P49: =CONFIG_REFERENCIA!$E$4 | Q49: =CONFIG_REFERENCIA!$E$5 | R49: =CONFIG_REFERENCIA!$E$6 | S49: =IF($F49="","",INDEX(CONFIG_REFERENCIA!$B$3:$B$6,MATCH($F49,CONFIG_REFERENCIA!$A$3:$A$6,0))) | X49: =IF(COUNTA($T49:$W49)<4,"",$S49*($O49*$T49+$P49*$U49+$Q49*$V49+$R49*$W49))
O50: =CONFIG_REFERENCIA!$E$3 | P50: =CONFIG_REFERENCIA!$E$4 | Q50: =CONFIG_REFERENCIA!$E$5 | R50: =CONFIG_REFERENCIA!$E$6 | S50: =IF($F50="","",INDEX(CONFIG_REFERENCIA!$B$3:$B$6,MATCH($F50,CONFIG_REFERENCIA!$A$3:$A$6,0))) | X50: =IF(COUNTA($T50:$W50)<4,"",$S50*($O50*$T50+$P50*$U50+$Q50*$V50+$R50*$W50))
O51: =CONFIG_REFERENCIA!$E$3 | P51: =CONFIG_REFERENCIA!$E$4 | Q51: =CONFIG_REFERENCIA!$E$5 | R51: =CONFIG_REFERENCIA!$E$6 | S51: =IF($F51="","",INDEX(CONFIG_REFERENCIA!$B$3:$B$6,MATCH($F51,CONFIG_REFERENCIA!$A$3:$A$6,0))) | X51: =IF(COUNTA($T51:$W51)<4,"",$S51*($O51*$T51+$P51*$U51+$Q51*$V51+$R51*$W51))
O52: =CONFIG_REFERENCIA!$E$3 | P52: =CONFIG_REFERENCIA!$E$4 | Q52: =CONFIG_REFERENCIA!$E$5 | R52: =CONFIG_REFERENCIA!$E$6 | S52: =IF($F52="","",INDEX(CONFIG_REFERENCIA!$B$3:$B$6,MATCH($F52,CONFIG_REFERENCIA!$A$3:$A$6,0))) | X52: =IF(COUNTA($T52:$W52)<4,"",$S52*($O52*$T52+$P52*$U52+$Q52*$V52+$R52*$W52))
O53: =CONFIG_REFERENCIA!$E$3 | P53: =CONFIG_REFERENCIA!$E$4 | Q53: =CONFIG_REFERENCIA!$E$5 | R53: =CONFIG_REFERENCIA!$E$6 | S53: =IF($F53="","",INDEX(CONFIG_REFERENCIA!$B$3:$B$6,MATCH($F53,CONFIG_REFERENCIA!$A$3:$A$6,0))) | X53: =IF(COUNTA($T53:$W53)<4,"",$S53*($O53*$T53+$P53*$U53+$Q53*$V53+$R53*$W53))
... O141: =CONFIG_REFERENCIA!$E$3 | P141: =CONFIG_REFERENCIA!$E$4 | Q141: =CONFIG_REFERENCIA!$E$5 | R141: =CONFIG_REFERENCIA!$E$6 | S141: =IF($F141="","",INDEX(CONFIG_REFERENCIA!$B$3:$B$6,MATCH($F141,CONFIG_REFERENCIA!$A$3:$A$6,0))) | X141: =IF(COUNTA($T141:$W141)<4,"",$S141*($O141*$T141+$P141*$U141+$Q141*$V141+$R141*$W141))
A142: 2026-03-21 08:39:22 | B142: E1_v2 | C142: E1 | D142: lineal_regularizado | E142: RidgeCV | F142: 1 | G142: nivel | H142: y_t + lags [1, 2, 3, 4] | I142: sentimiento_medios, v5_agua_neto, v5_alumbrado_neto, v5_americo_neto, v5_basura_neto, v5_corrupcion_neto, v5_delitos_neto, v5_morena_neto, v5_obras_neto, v5_prevencion_neto, v5_vialidad_neto | J142: standard_scaler | K142: all | L142: walk-forward_expanding | M142: 2024-10-14 a 2026-03-02 | N142: {"feature_candidates": 59, "feature_mode": "all", "horizon": 1, "initial_train_size": 40, "lags": [1, 2, 3, 4], "model": "RidgeCV", "model_params": {"alphas": [0.0001, 0.00015848931924611142, 0.00025118864315095795, 0.00039810717055349735, 0.000630957344480193, 0.001, 0.001584893192461114, 0.002511886431509582, 0.003981071705534973, 0.006309573444801929, 0.01, 0.01584893192461114, 0.025118864315095822, 0.039810717055349734, 0.06309573444801936, 0.1, 0.1584893192461114, 0.25118864315095824, 0.3981071705534973, 0.6309573444801936, 1.0, 1.584893192461114, 2.5118864315095824, 3.9810717055349776, 6.309573444801943, 10.0, 15.848931924611142, 25.11886431509582, 39.81071705534978, 63.09573444801943, 100.0, 158.48931924611142, 251.18864315095823, 398.1071705534977, 630.9573444801943, 1000.0, 1584.893192461114, 2511.886431509582, 3981.0717055349774, 6309.573444801943, 10000.0], "transform_mode": "standard", "winsor_lower_quantile": 0.05, "winsor_upper_quantile": 0.95}, "rows_eval": 28, "rows_modeling": 68, "selected_feature_count_avg": 59.0, "target_mode": "nivel", "transform_mode": "standard"} | O142: 0.35 | P142: 0.25 | Q142: 0.25 | R142: 0.1 | S142: 0.3 | T142: 0.17637742 | U142: 0.17857143 | V142: 0.23076923 | W142: 0.78571429 | X142: 0.072791607 | Y142: 0.10852222 | Z142: 0.13647812 | AA142: 0.82142857 | AB142: 0.76923077 | AC142: corrido | AD142: Familia lineal regularizada con RidgeCV | transform_mode=standard. | AE142: run_e1_ridge.py | AF142: Scripts/Modeling/run_e1_ridge.py | AG142: Experimentos/runs/E1_v2_20260321_083922 | AH142: Experimentos/runs/E1_v2_20260321_083922/scripts/run_e1_ridge.py | AI142: Experimentos/runs/E1_v2_20260321_083922/parametros_run.json | AJ142: Experimentos/runs/E1_v2_20260321_083922/metricas_horizonte.json | AK142: 2026-03-21 08:39:22
A143: 2026-03-21 08:39:22 | B143: E1_v2 | C143: E1 | D143: lineal_regularizado | E143: RidgeCV | F143: 2 | G143: nivel | H143: y_t + lags [1, 2, 3, 4] | I143: sentimiento_medios, v5_agua_neto, v5_alumbrado_neto, v5_americo_neto, v5_basura_neto, v5_corrupcion_neto, v5_delitos_neto, v5_morena_neto, v5_obras_neto, v5_prevencion_neto, v5_vialidad_neto | J143: standard_scaler | K143: all | L143: walk-forward_expanding | M143: 2024-10-14 a 2026-03-02 | N143: {"feature_candidates": 59, "feature_mode": "all", "horizon": 2, "initial_train_size": 40, "lags": [1, 2, 3, 4], "model": "RidgeCV", "model_params": {"alphas": [0.0001, 0.00015848931924611142, 0.00025118864315095795, 0.00039810717055349735, 0.000630957344480193, 0.001, 0.001584893192461114, 0.002511886431509582, 0.003981071705534973, 0.006309573444801929, 0.01, 0.01584893192461114, 0.025118864315095822, 0.039810717055349734, 0.06309573444801936, 0.1, 0.1584893192461114, 0.25118864315095824, 0.3981071705534973, 0.6309573444801936, 1.0, 1.584893192461114, 2.5118864315095824, 3.9810717055349776, 6.309573444801943, 10.0, 15.848931924611142, 25.11886431509582, 39.81071705534978, 63.09573444801943, 100.0, 158.48931924611142, 251.18864315095823, 398.1071705534977, 630.9573444801943, 1000.0, 1584.893192461114, 2511.886431509582, 3981.0717055349774, 6309.573444801943, 10000.0], "transform_mode": "standard", "winsor_lower_quantile": 0.05, "winsor_upper_quantile": 0.95}, "rows_eval": 27, "rows_modeling": 67, "selected_feature_count_avg": 59.0, "target_mode": "nivel", "transform_mode": "standard"} | O143: 0.35 | P143: 0.25 | Q143: 0.25 | R143: 0.1 | S143: 0.25 | T143: 0.1677302 | U143: 0.40740741 | V143: 0.41666667 | W143: 0.77777778 | X143: 0.085625466 | Y143: 0.10320172 | Z143: 0.13166084 | AA143: 0.59259259 | AB143: 0.58333333 | AC143: corrido | AD143: Familia lineal regularizada con RidgeCV | transform_mode=standard. | AE143: run_e1_ridge.py | AF143: Scripts/Modeling/run_e1_ridge.py | AG143: Experimentos/runs/E1_v2_20260321_083922 | AH143: Experimentos/runs/E1_v2_20260321_083922/scripts/run_e1_ridge.py | AI143: Experimentos/runs/E1_v2_20260321_083922/parametros_run.json | AJ143: Experimentos/runs/E1_v2_20260321_083922/metricas_horizonte.json | AK143: 2026-03-21 08:39:22
A144: 2026-03-21 08:39:22 | B144: E1_v2 | C144: E1 | D144: lineal_regularizado | E144: RidgeCV | F144: 3 | G144: nivel | H144: y_t + lags [1, 2, 3, 4] | I144: sentimiento_medios, v5_agua_neto, v5_alumbrado_neto, v5_americo_neto, v5_basura_neto, v5_corrupcion_neto, v5_delitos_neto, v5_morena_neto, v5_obras_neto, v5_prevencion_neto, v5_vialidad_neto | J144: standard_scaler | K144: all | L144: walk-forward_expanding | M144: 2024-10-14 a 2026-03-02 | N144: {"feature_candidates": 59, "feature_mode": "all", "horizon": 3, "initial_train_size": 40, "lags": [1, 2, 3, 4], "model": "RidgeCV", "model_params": {"alphas": [0.0001, 0.00015848931924611142, 0.00025118864315095795, 0.00039810717055349735, 0.000630957344480193, 0.001, 0.001584893192461114, 0.002511886431509582, 0.003981071705534973, 0.006309573444801929, 0.01, 0.01584893192461114, 0.025118864315095822, 0.039810717055349734, 0.06309573444801936, 0.1, 0.1584893192461114, 0.25118864315095824, 0.3981071705534973, 0.6309573444801936, 1.0, 1.584893192461114, 2.5118864315095824, 3.9810717055349776, 6.309573444801943, 10.0, 15.848931924611142, 25.11886431509582, 39.81071705534978, 63.09573444801943, 100.0, 158.48931924611142, 251.18864315095823, 398.1071705534977, 630.9573444801943, 1000.0, 1584.893192461114, 2511.886431509582, 3981.0717055349774, 6309.573444801943, 10000.0], "transform_mode": "standard", "winsor_lower_quantile": 0.05, "winsor_upper_quantile": 0.95}, "rows_eval": 26, "rows_modeling": 66, "selected_feature_count_avg": 59.0, "target_mode": "nivel", "transform_mode": "standard"} | O144: 0.35 | P144: 0.25 | Q144: 0.25 | R144: 0.1 | S144: 0.3 | T144: 0.17167648 | U144: 0.15384615 | V144: 0.16666667 | W144: 0.76923077 | X144: 0.065141415 | Y144: 0.1056298 | Z144: 0.13719619 | AA144: 0.84615385 | AB144: 0.83333333 | AC144: corrido | AD144: Familia lineal regularizada con RidgeCV | transform_mode=standard. | AE144: run_e1_ridge.py | AF144: Scripts/Modeling/run_e1_ridge.py | AG144: Experimentos/runs/E1_v2_20260321_083922 | AH144: Experimentos/runs/E1_v2_20260321_083922/scripts/run_e1_ridge.py | AI144: Experimentos/runs/E1_v2_20260321_083922/parametros_run.json | AJ144: Experimentos/runs/E1_v2_20260321_083922/metricas_horizonte.json | AK144: 2026-03-21 08:39:22
A145: 2026-03-21 08:39:22 | B145: E1_v2 | C145: E1 | D145: lineal_regularizado | E145: RidgeCV | F145: 4 | G145: nivel | H145: y_t + lags [1, 2, 3, 4] | I145: sentimiento_medios, v5_agua_neto, v5_alumbrado_neto, v5_americo_neto, v5_basura_neto, v5_corrupcion_neto, v5_delitos_neto, v5_morena_neto, v5_obras_neto, v5_prevencion_neto, v5_vialidad_neto | J145: standard_scaler | K145: all | L145: walk-forward_expanding | M145: 2024-10-14 a 2026-03-02 | N145: {"feature_candidates": 59, "feature_mode": "all", "horizon": 4, "initial_train_size": 40, "lags": [1, 2, 3, 4], "model": "RidgeCV", "model_params": {"alphas": [0.0001, 0.00015848931924611142, 0.00025118864315095795, 0.00039810717055349735, 0.000630957344480193, 0.001, 0.001584893192461114, 0.002511886431509582, 0.003981071705534973, 0.006309573444801929, 0.01, 0.01584893192461114, 0.025118864315095822, 0.039810717055349734, 0.06309573444801936, 0.1, 0.1584893192461114, 0.25118864315095824, 0.3981071705534973, 0.6309573444801936, 1.0, 1.584893192461114, 2.5118864315095824, 3.9810717055349776, 6.309573444801943, 10.0, 15.848931924611142, 25.11886431509582, 39.81071705534978, 63.09573444801943, 100.0, 158.48931924611142, 251.18864315095823, 398.1071705534977, 630.9573444801943, 1000.0, 1584.893192461114, 2511.886431509582, 3981.0717055349774, 6309.573444801943, 10000.0], "transform_mode": "standard", "winsor_lower_quantile": 0.05, "winsor_upper_quantile": 0.95}, "rows_eval": 25, "rows_modeling": 65, "selected_feature_count_avg": 59.0, "target_mode": "nivel", "transform_mode": "standard"} | O145: 0.35 | P145: 0.25 | Q145: 0.25 | R145: 0.1 | S145: 0.15 | T145: 0.16576782 | U145: 0.28 | V145: 0.2 | W145: 0.72 | X145: 0.037502811 | Y145: 0.1019943 | Z145: 0.13564279 | AA145: 0.72 | AB145: 0.8 | AC145: corrido | AD145: Familia lineal regularizada con RidgeCV | transform_mode=standard. | AE145: run_e1_ridge.py | AF145: Scripts/Modeling/run_e1_ridge.py | AG145: Experimentos/runs/E1_v2_20260321_083922 | AH145: Experimentos/runs/E1_v2_20260321_083922/scripts/run_e1_ridge.py | AI145: Experimentos/runs/E1_v2_20260321_083922/parametros_run.json | AJ145: Experimentos/runs/E1_v2_20260321_083922/metricas_horizonte.json | AK145: 2026-03-21 08:39:22
A146: 2026-03-21 09:42:41 | B146: E1_v2_clean | C146: E1 | D146: lineal_regularizado | E146: ridge_tscv | F146: 1 | G146: nivel | H146: y_t + lags [1, 2, 3, 4] | I146: sentimiento_medios, v5_agua_neto, v5_alumbrado_neto, v5_americo_neto, v5_basura_neto, v5_corrupcion_neto, v5_delitos_neto, v5_morena_neto, v5_obras_neto, v5_prevencion_neto, v5_vialidad_neto | J146: standard_scaler | K146: all | L146: walk-forward_expanding | M146: 2024-10-14 a 2026-03-02 | N146: {"feature_candidates": 59, "feature_mode": "all", "horizon": 1, "initial_train_size": 40, "lags": [1, 2, 3, 4], "model": "ridge_tscv", "model_params": {"alpha_grid": [0.0001, 0.0001603718743751331, 0.00025719138090593444, 0.0004124626382901352, 0.0006614740641230146, 0.0010608183551394483, 0.0017012542798525892, 0.0027283333764867696, 0.004375479375074184, 0.007017038286703823, 0.011253355826007646, 0.018047217668271703, 0.028942661247167517, 0.046415888336127774, 0.07443803013251689, 0.11937766417144358, 0.19144819761699575, 0.30702906297578497, 0.49238826317067363, 0.7896522868499725, 1.266380173467402, 2.030917620904735, 3.257020655659783, 5.2233450742668435, 8.376776400682925, 13.433993325988988, 21.54434690031882, 34.55107294592218, 55.41020330009492, 88.86238162743408, 142.51026703029962, 228.54638641349882, 366.5241237079626, 587.8016072274912, 942.6684551178854, 1511.77507061566, 2424.462017082326, 3888.155180308085, 6235.507341273912, 10000.0], "alpha_selection_metric": "mae", "inner_splits": 3, "transform_mode": "standard", "winsor_lower_quantile": 0.05, "winsor_upper_quantile": 0.95}, "rows_eval": 28, "rows_modeling": 68, "selected_feature_count_avg": 59.0, "target_mode": "nivel", "transform_mode": "standard"} | O146: 0.35 | P146: 0.25 | Q146: 0.25 | R146: 0.1 | S146: 0.3 | T146: 0.17686098 | U146: 0.17857143 | V146: 0.23076923 | W146: 0.85714286 | X146: 0.074985238 | Y146: 0.10881974 | Z146: 0.13402141 | AA146: 0.82142857 | AB146: 0.76923077 | AC146: corrido | AD146: Ridge limpio con tuning temporal interno | metric=mae | inner_splits=3 | AE146: run_e1_ridge_clean.py | AF146: Scripts/Modeling/run_e1_ridge_clean.py | AG146: Experimentos/runs/E1_v2_clean_20260321_094241 | AH146: Experimentos/runs/E1_v2_clean_20260321_094241/scripts/run_e1_ridge_clean.py | AI146: Experimentos/runs/E1_v2_clean_20260321_094241/parametros_run.json | AJ146: Experimentos/runs/E1_v2_clean_20260321_094241/metricas_horizonte.json | AK146: 2026-03-21 09:42:41
A147: 2026-03-21 09:42:41 | B147: E1_v2_clean | C147: E1 | D147: lineal_regularizado | E147: ridge_tscv | F147: 2 | G147: nivel | H147: y_t + lags [1, 2, 3, 4] | I147: sentimiento_medios, v5_agua_neto, v5_alumbrado_neto, v5_americo_neto, v5_basura_neto, v5_corrupcion_neto, v5_delitos_neto, v5_morena_neto, v5_obras_neto, v5_prevencion_neto, v5_vialidad_neto | J147: standard_scaler | K147: all | L147: walk-forward_expanding | M147: 2024-10-14 a 2026-03-02 | N147: {"feature_candidates": 59, "feature_mode": "all", "horizon": 2, "initial_train_size": 40, "lags": [1, 2, 3, 4], "model": "ridge_tscv", "model_params": {"alpha_grid": [0.0001, 0.0001603718743751331, 0.00025719138090593444, 0.0004124626382901352, 0.0006614740641230146, 0.0010608183551394483, 0.0017012542798525892, 0.0027283333764867696, 0.004375479375074184, 0.007017038286703823, 0.011253355826007646, 0.018047217668271703, 0.028942661247167517, 0.046415888336127774, 0.07443803013251689, 0.11937766417144358, 0.19144819761699575, 0.30702906297578497, 0.49238826317067363, 0.7896522868499725, 1.266380173467402, 2.030917620904735, 3.257020655659783, 5.2233450742668435, 8.376776400682925, 13.433993325988988, 21.54434690031882, 34.55107294592218, 55.41020330009492, 88.86238162743408, 142.51026703029962, 228.54638641349882, 366.5241237079626, 587.8016072274912, 942.6684551178854, 1511.77507061566, 2424.462017082326, 3888.155180308085, 6235.507341273912, 10000.0], "alpha_selection_metric": "mae", "inner_splits": 3, "transform_mode": "standard", "winsor_lower_quantile": 0.05, "winsor_upper_quantile": 0.95}, "rows_eval": 27, "rows_modeling": 67, "selected_feature_count_avg": 59.0, "target_mode": "nivel", "transform_mode": "standard"} | O147: 0.35 | P147: 0.25 | Q147: 0.25 | R147: 0.1 | S147: 0.25 | T147: 0.16499158 | U147: 0.40740741 | V147: 0.41666667 | W147: 0.74074074 | X147: 0.084459912 | Y147: 0.10151669 | Z147: 0.12902048 | AA147: 0.59259259 | AB147: 0.58333333 | AC147: corrido | AD147: Ridge limpio con tuning temporal interno | metric=mae | inner_splits=3 | AE147: run_e1_ridge_clean.py | AF147: Scripts/Modeling/run_e1_ridge_clean.py | AG147: Experimentos/runs/E1_v2_clean_20260321_094241 | AH147: Experimentos/runs/E1_v2_clean_20260321_094241/scripts/run_e1_ridge_clean.py | AI147: Experimentos/runs/E1_v2_clean_20260321_094241/parametros_run.json | AJ147: Experimentos/runs/E1_v2_clean_20260321_094241/metricas_horizonte.json | AK147: 2026-03-21 09:42:41
A148: 2026-03-21 09:42:41 | B148: E1_v2_clean | C148: E1 | D148: lineal_regularizado | E148: ridge_tscv | F148: 3 | G148: nivel | H148: y_t + lags [1, 2, 3, 4] | I148: sentimiento_medios, v5_agua_neto, v5_alumbrado_neto, v5_americo_neto, v5_basura_neto, v5_corrupcion_neto, v5_delitos_neto, v5_morena_neto, v5_obras_neto, v5_prevencion_neto, v5_vialidad_neto | J148: standard_scaler | K148: all | L148: walk-forward_expanding | M148: 2024-10-14 a 2026-03-02 | N148: {"feature_candidates": 59, "feature_mode": "all", "horizon": 3, "initial_train_size": 40, "lags": [1, 2, 3, 4], "model": "ridge_tscv", "model_params": {"alpha_grid": [0.0001, 0.0001603718743751331, 0.00025719138090593444, 0.0004124626382901352, 0.0006614740641230146, 0.0010608183551394483, 0.0017012542798525892, 0.0027283333764867696, 0.004375479375074184, 0.007017038286703823, 0.011253355826007646, 0.018047217668271703, 0.028942661247167517, 0.046415888336127774, 0.07443803013251689, 0.11937766417144358, 0.19144819761699575, 0.30702906297578497, 0.49238826317067363, 0.7896522868499725, 1.266380173467402, 2.030917620904735, 3.257020655659783, 5.2233450742668435, 8.376776400682925, 13.433993325988988, 21.54434690031882, 34.55107294592218, 55.41020330009492, 88.86238162743408, 142.51026703029962, 228.54638641349882, 366.5241237079626, 587.8016072274912, 942.6684551178854, 1511.77507061566, 2424.462017082326, 3888.155180308085, 6235.507341273912, 10000.0], "alpha_selection_metric": "mae", "inner_splits": 3, "transform_mode": "standard", "winsor_lower_quantile": 0.05, "winsor_upper_quantile": 0.95}, "rows_eval": 26, "rows_modeling": 66, "selected_feature_count_avg": 59.0, "target_mode": "nivel", "transform_mode": "standard"} | O148: 0.35 | P148: 0.25 | Q148: 0.25 | R148: 0.1 | S148: 0.3 | T148: 0.16369718 | U148: 0.15384615 | V148: 0.16666667 | W148: 0.76923077 | X148: 0.064303588 | Y148: 0.10072026 | Z148: 0.13035148 | AA148: 0.84615385 | AB148: 0.83333333 | AC148: corrido | AD148: Ridge limpio con tuning temporal interno | metric=mae | inner_splits=3 | AE148: run_e1_ridge_clean.py | AF148: Scripts/Modeling/run_e1_ridge_clean.py | AG148: Experimentos/runs/E1_v2_clean_20260321_094241 | AH148: Experimentos/runs/E1_v2_clean_20260321_094241/scripts/run_e1_ridge_clean.py | AI148: Experimentos/runs/E1_v2_clean_20260321_094241/parametros_run.json | AJ148: Experimentos/runs/E1_v2_clean_20260321_094241/metricas_horizonte.json | AK148: 2026-03-21 09:42:41
A149: 2026-03-21 09:42:41 | B149: E1_v2_clean | C149: E1 | D149: lineal_regularizado | E149: ridge_tscv | F149: 4 | G149: nivel | H149: y_t + lags [1, 2, 3, 4] | I149: sentimiento_medios, v5_agua_neto, v5_alumbrado_neto, v5_americo_neto, v5_basura_neto, v5_corrupcion_neto, v5_delitos_neto, v5_morena_neto, v5_obras_neto, v5_prevencion_neto, v5_vialidad_neto | J149: standard_scaler | K149: all | L149: walk-forward_expanding | M149: 2024-10-14 a 2026-03-02 | N149: {"feature_candidates": 59, "feature_mode": "all", "horizon": 4, "initial_train_size": 40, "lags": [1, 2, 3, 4], "model": "ridge_tscv", "model_params": {"alpha_grid": [0.0001, 0.0001603718743751331, 0.00025719138090593444, 0.0004124626382901352, 0.0006614740641230146, 0.0010608183551394483, 0.0017012542798525892, 0.0027283333764867696, 0.004375479375074184, 0.007017038286703823, 0.011253355826007646, 0.018047217668271703, 0.028942661247167517, 0.046415888336127774, 0.07443803013251689, 0.11937766417144358, 0.19144819761699575, 0.30702906297578497, 0.49238826317067363, 0.7896522868499725, 1.266380173467402, 2.030917620904735, 3.257020655659783, 5.2233450742668435, 8.376776400682925, 13.433993325988988, 21.54434690031882, 34.55107294592218, 55.41020330009492, 88.86238162743408, 142.51026703029962, 228.54638641349882, 366.5241237079626, 587.8016072274912, 942.6684551178854, 1511.77507061566, 2424.462017082326, 3888.155180308085, 6235.507341273912, 10000.0], "alpha_selection_metric": "mae", "inner_splits": 3, "transform_mode": "standard", "winsor_lower_quantile": 0.05, "winsor_upper_quantile": 0.95}, "rows_eval": 25, "rows_modeling": 65, "selected_feature_count_avg": 59.0, "target_mode": "nivel", "transform_mode": "standard"} | O149: 0.35 | P149: 0.25 | Q149: 0.25 | R149: 0.1 | S149: 0.15 | T149: 0.16552252 | U149: 0.28 | V149: 0.2 | W149: 0.72 | X149: 0.037489932 | Y149: 0.10184337 | Z149: 0.13551179 | AA149: 0.72 | AB149: 0.8 | AC149: corrido | AD149: Ridge limpio con tuning temporal interno | metric=mae | inner_splits=3 | AE149: run_e1_ridge_clean.py | AF149: Scripts/Modeling/run_e1_ridge_clean.py | AG149: Experimentos/runs/E1_v2_clean_20260321_094241 | AH149: Experimentos/runs/E1_v2_clean_20260321_094241/scripts/run_e1_ridge_clean.py | AI149: Experimentos/runs/E1_v2_clean_20260321_094241/parametros_run.json | AJ149: Experimentos/runs/E1_v2_clean_20260321_094241/metricas_horizonte.json | AK149: 2026-03-21 09:42:41
A150: 2026-03-21 10:32:56 | B150: E1_v3_clean | C150: E1 | D150: lineal_regularizado | E150: ridge_tscv | F150: 1 | G150: delta | H150: y_t + lags [1, 2, 3, 4] | I150: sentimiento_medios, v5_agua_neto, v5_alumbrado_neto, v5_americo_neto, v5_basura_neto, v5_corrupcion_neto, v5_delitos_neto, v5_morena_neto, v5_obras_neto, v5_prevencion_neto, v5_vialidad_neto | J150: standard_scaler | K150: all | L150: walk-forward_expanding | M150: 2024-10-14 a 2026-03-02 | N150: {"feature_candidates": 59, "feature_mode": "all", "horizon": 1, "initial_train_size": 40, "lags": [1, 2, 3, 4], "model": "ridge_tscv", "model_params": {"alpha_grid": [0.0001, 0.0001603718743751331, 0.00025719138090593444, 0.0004124626382901352, 0.0006614740641230146, 0.0010608183551394483, 0.0017012542798525892, 0.0027283333764867696, 0.004375479375074184, 0.007017038286703823, 0.011253355826007646, 0.018047217668271703, 0.028942661247167517, 0.046415888336127774, 0.07443803013251689, 0.11937766417144358, 0.19144819761699575, 0.30702906297578497, 0.49238826317067363, 0.7896522868499725, 1.266380173467402, 2.030917620904735, 3.257020655659783, 5.2233450742668435, 8.376776400682925, 13.433993325988988, 21.54434690031882, 34.55107294592218, 55.41020330009492, 88.86238162743408, 142.51026703029962, 228.54638641349882, 366.5241237079626, 587.8016072274912, 942.6684551178854, 1511.77507061566, 2424.462017082326, 3888.155180308085, 6235.507341273912, 10000.0], "alpha_selection_metric": "mae", "inner_splits": 3, "transform_mode": "standard", "winsor_lower_quantile": 0.05, "winsor_upper_quantile": 0.95}, "rows_eval": 28, "rows_modeling": 68, "selected_feature_count_avg": 59.0, "target_mode": "delta", "transform_mode": "standard"} | O150: 0.35 | P150: 0.25 | Q150: 0.25 | R150: 0.1 | S150: 0.3 | T150: 0.26547687 | U150: 0.71428571 | V150: 0.46153846 | W150: 0.78571429 | X150: 0.13963331 | Y150: 0.16334369 | Z150: 0.20455768 | AA150: 0.28571429 | AB150: 0.53846154 | AC150: corrido | AD150: Ridge limpio con tuning temporal interno | metric=mae | inner_splits=3 | AE150: run_e1_ridge_clean.py | AF150: Scripts/Modeling/run_e1_ridge_clean.py | AG150: Experimentos/runs/E1_v3_clean_20260321_103256 | AH150: Experimentos/runs/E1_v3_clean_20260321_103256/scripts/run_e1_ridge_clean.py | AI150: Experimentos/runs/E1_v3_clean_20260321_103256/parametros_run.json | AJ150: Experimentos/runs/E1_v3_clean_20260321_103256/metricas_horizonte.json | AK150: 2026-03-21 10:32:56
...

Sheet RUN_SUMMARY
A1: Run_ID | B1: Experiment_ID | C1: Modelo | D1: Familia | E1: Horizons_loaded | F1: Sum_weighted_Loss_h | G1: L_coh | H1: eta | I1: L_total_Radar | J1: Avg_MAE | K1: Avg_RMSE | L1: Dir_acc_prom | M1: Det_caidas_prom | N1: Decision | O1: Ranking | P1: Comentarios | Q1: Script_nombre | R1: Script_ruta | S1: Run_dir | T1: Snapshot_script | U1: Parametros_ruta_json | V1: Resultados_ruta_json | W1: Timestamp_run | X1: Task_type | Y1: L_total_Clasificacion | Z1: Avg_Accuracy_5clases | AA1: Avg_Balanced_accuracy_5clases | AB1: Avg_Macro_f1_5clases | AC1: Avg_Weighted_f1_5clases | AD1: Avg_Recall_baja_fuerte | AE1: Avg_Recall_baja_total | AF1: Avg_Precision_baja_fuerte | AG1: Avg_Recall_sube_fuerte | AH1: Avg_Recall_sube_total | AI1: Avg_Accuracy_3clases | AJ1: Avg_Macro_f1_3clases | AK1: Avg_Balanced_accuracy_3clases
A2: E1_v1 | B2: E1 | C2: RidgeCV | D2: lineal | E2: 4 | F2: 0.2610613 | H2: 0.05 | I2: 0.2610613 | J2: 0.10483701 | K2: 0.13524448 | L2: 0.74504375 | M2: 0.74647436 | P2: Retrointegrado desde metricas_horizonte.json para persistir resumen numerico. | Q2: run_e1_ridge.py | R2: Scripts/Modeling/run_e1_ridge.py | S2: Experimentos/runs/E1_v1_20260321_063715 | T2: Experimentos/runs/E1_v1_20260321_063715/scripts/run_e1_ridge.py | U2: Experimentos/runs/E1_v1_20260321_063715/parametros_run.json | V2: Experimentos/runs/E1_v1_20260321_063715/metricas_horizonte.json | W2: 2026-03-21 06:37:15
A3: E2_v1 | B3: =IF($A3="","",IFERROR(INDEX(RESULTADOS_GRID!$C:$C,MATCH($A3,RESULTADOS_GRID!$B:$B,0)),"")) | C3: =IF($A3="","",IFERROR(INDEX(RESULTADOS_GRID!$E:$E,MATCH($A3,RESULTADOS_GRID!$B:$B,0)),"")) | D3: =IF($A3="","",IFERROR(INDEX(RESULTADOS_GRID!$D:$D,MATCH($A3,RESULTADOS_GRID!$B:$B,0)),"")) | E3: =IF($A3="","",COUNTIF(RESULTADOS_GRID!$B:$B,$A3)) | F3: =IF($A3="","",SUMIF(RESULTADOS_GRID!$B:$B,$A3,RESULTADOS_GRID!$X:$X)) | H3: =CONFIG_REFERENCIA!$E$7 | I3: =IF($A3="","",$F3+N($G3)*$H3) | J3: =IF($A3="","",IF((COUNTIFS(RESULTADOS_GRID!$B:$B,$A3,RESULTADOS_GRID!$Y:$Y,">=0")+COUNTIFS(RESULTADOS_GRID!$B:$B,$A3,RESULTADOS_GRID!$Y:$Y,"<0"))=0,"",SUMIF(RESULTADOS_GRID!$B:$B,$A3,RESULTADOS_GRID!$Y:$Y)/(COUNTIFS(RESULTADOS_GRID!$B:$B,$A3,RESULTADOS_GRID!$Y:$Y,">=0")+COUNTIFS(RESULTADOS_GRID!$B:$B,$A3,RESULTADOS_GRID!$Y:$Y,"<0")))) | K3: =IF($A3="","",IF((COUNTIFS(RESULTADOS_GRID!$B:$B,$A3,RESULTADOS_GRID!$Z:$Z,">=0")+COUNTIFS(RESULTADOS_GRID!$B:$B,$A3,RESULTADOS_GRID!$Z:$Z,"<0"))=0,"",SUMIF(RESULTADOS_GRID!$B:$B,$A3,RESULTADOS_GRID!$Z:$Z)/(COUNTIFS(RESULTADOS_GRID!$B:$B,$A3,RESULTADOS_GRID!$Z:$Z,">=0")+COUNTIFS(RESULTADOS_GRID!$B:$B,$A3,RESULTADOS_GRID!$Z:$Z,"<0")))) | L3: =IF($A3="","",IF((COUNTIFS(RESULTADOS_GRID!$B:$B,$A3,RESULTADOS_GRID!$AA:$AA,">=0")+COUNTIFS(RESULTADOS_GRID!$B:$B,$A3,RESULTADOS_GRID!$AA:$AA,"<0"))=0,"",SUMIF(RESULTADOS_GRID!$B:$B,$A3,RESULTADOS_GRID!$AA:$AA)/(COUNTIFS(RESULTADOS_GRID!$B:$B,$A3,RESULTADOS_GRID!$AA:$AA,">=0")+COUNTIFS(RESULTADOS_GRID!$B:$B,$A3,RESULTADOS_GRID!$AA:$AA,"<0")))) | M3: =IF($A3="","",IF((COUNTIFS(RESULTADOS_GRID!$B:$B,$A3,RESULTADOS_GRID!$AB:$AB,">=0")+COUNTIFS(RESULTADOS_GRID!$B:$B,$A3,RESULTADOS_GRID!$AB:$AB,"<0"))=0,"",SUMIF(RESULTADOS_GRID!$B:$B,$A3,RESULTADOS_GRID!$AB:$AB)/(COUNTIFS(RESULTADOS_GRID!$B:$B,$A3,RESULTADOS_GRID!$AB:$AB,">=0")+COUNTIFS(RESULTADOS_GRID!$B:$B,$A3,RESULTADOS_GRID!$AB:$AB,"<0")))) | O3: =IF($I3="","",COUNTIFS($I$2:$I$101,"<"&$I3)+1)
A4: E3_v1 | B4: =IF($A4="","",IFERROR(INDEX(RESULTADOS_GRID!$C:$C,MATCH($A4,RESULTADOS_GRID!$B:$B,0)),"")) | C4: =IF($A4="","",IFERROR(INDEX(RESULTADOS_GRID!$E:$E,MATCH($A4,RESULTADOS_GRID!$B:$B,0)),"")) | D4: =IF($A4="","",IFERROR(INDEX(RESULTADOS_GRID!$D:$D,MATCH($A4,RESULTADOS_GRID!$B:$B,0)),"")) | E4: =IF($A4="","",COUNTIF(RESULTADOS_GRID!$B:$B,$A4)) | F4: =IF($A4="","",SUMIF(RESULTADOS_GRID!$B:$B,$A4,RESULTADOS_GRID!$X:$X)) | H4: =CONFIG_REFERENCIA!$E$7 | I4: =IF($A4="","",$F4+N($G4)*$H4) | J4: =IF($A4="","",IF((COUNTIFS(RESULTADOS_GRID!$B:$B,$A4,RESULTADOS_GRID!$Y:$Y,">=0")+COUNTIFS(RESULTADOS_GRID!$B:$B,$A4,RESULTADOS_GRID!$Y:$Y,"<0"))=0,"",SUMIF(RESULTADOS_GRID!$B:$B,$A4,RESULTADOS_GRID!$Y:$Y)/(COUNTIFS(RESULTADOS_GRID!$B:$B,$A4,RESULTADOS_GRID!$Y:$Y,">=0")+COUNTIFS(RESULTADOS_GRID!$B:$B,$A4,RESULTADOS_GRID!$Y:$Y,"<0")))) | K4: =IF($A4="","",IF((COUNTIFS(RESULTADOS_GRID!$B:$B,$A4,RESULTADOS_GRID!$Z:$Z,">=0")+COUNTIFS(RESULTADOS_GRID!$B:$B,$A4,RESULTADOS_GRID!$Z:$Z,"<0"))=0,"",SUMIF(RESULTADOS_GRID!$B:$B,$A4,RESULTADOS_GRID!$Z:$Z)/(COUNTIFS(RESULTADOS_GRID!$B:$B,$A4,RESULTADOS_GRID!$Z:$Z,">=0")+COUNTIFS(RESULTADOS_GRID!$B:$B,$A4,RESULTADOS_GRID!$Z:$Z,"<0")))) | L4: =IF($A4="","",IF((COUNTIFS(RESULTADOS_GRID!$B:$B,$A4,RESULTADOS_GRID!$AA:$AA,">=0")+COUNTIFS(RESULTADOS_GRID!$B:$B,$A4,RESULTADOS_GRID!$AA:$AA,"<0"))=0,"",SUMIF(RESULTADOS_GRID!$B:$B,$A4,RESULTADOS_GRID!$AA:$AA)/(COUNTIFS(RESULTADOS_GRID!$B:$B,$A4,RESULTADOS_GRID!$AA:$AA,">=0")+COUNTIFS(RESULTADOS_GRID!$B:$B,$A4,RESULTADOS_GRID!$AA:$AA,"<0")))) | M4: =IF($A4="","",IF((COUNTIFS(RESULTADOS_GRID!$B:$B,$A4,RESULTADOS_GRID!$AB:$AB,">=0")+COUNTIFS(RESULTADOS_GRID!$B:$B,$A4,RESULTADOS_GRID!$AB:$AB,"<0"))=0,"",SUMIF(RESULTADOS_GRID!$B:$B,$A4,RESULTADOS_GRID!$AB:$AB)/(COUNTIFS(RESULTADOS_GRID!$B:$B,$A4,RESULTADOS_GRID!$AB:$AB,">=0")+COUNTIFS(RESULTADOS_GRID!$B:$B,$A4,RESULTADOS_GRID!$AB:$AB,"<0")))) | O4: =IF($I4="","",COUNTIFS($I$2:$I$101,"<"&$I4)+1)
A5: E4_v1 | B5: =IF($A5="","",IFERROR(INDEX(RESULTADOS_GRID!$C:$C,MATCH($A5,RESULTADOS_GRID!$B:$B,0)),"")) | C5: =IF($A5="","",IFERROR(INDEX(RESULTADOS_GRID!$E:$E,MATCH($A5,RESULTADOS_GRID!$B:$B,0)),"")) | D5: =IF($A5="","",IFERROR(INDEX(RESULTADOS_GRID!$D:$D,MATCH($A5,RESULTADOS_GRID!$B:$B,0)),"")) | E5: =IF($A5="","",COUNTIF(RESULTADOS_GRID!$B:$B,$A5)) | F5: =IF($A5="","",SUMIF(RESULTADOS_GRID!$B:$B,$A5,RESULTADOS_GRID!$X:$X)) | H5: =CONFIG_REFERENCIA!$E$7 | I5: =IF($A5="","",$F5+N($G5)*$H5) | J5: =IF($A5="","",IF((COUNTIFS(RESULTADOS_GRID!$B:$B,$A5,RESULTADOS_GRID!$Y:$Y,">=0")+COUNTIFS(RESULTADOS_GRID!$B:$B,$A5,RESULTADOS_GRID!$Y:$Y,"<0"))=0,"",SUMIF(RESULTADOS_GRID!$B:$B,$A5,RESULTADOS_GRID!$Y:$Y)/(COUNTIFS(RESULTADOS_GRID!$B:$B,$A5,RESULTADOS_GRID!$Y:$Y,">=0")+COUNTIFS(RESULTADOS_GRID!$B:$B,$A5,RESULTADOS_GRID!$Y:$Y,"<0")))) | K5: =IF($A5="","",IF((COUNTIFS(RESULTADOS_GRID!$B:$B,$A5,RESULTADOS_GRID!$Z:$Z,">=0")+COUNTIFS(RESULTADOS_GRID!$B:$B,$A5,RESULTADOS_GRID!$Z:$Z,"<0"))=0,"",SUMIF(RESULTADOS_GRID!$B:$B,$A5,RESULTADOS_GRID!$Z:$Z)/(COUNTIFS(RESULTADOS_GRID!$B:$B,$A5,RESULTADOS_GRID!$Z:$Z,">=0")+COUNTIFS(RESULTADOS_GRID!$B:$B,$A5,RESULTADOS_GRID!$Z:$Z,"<0")))) | L5: =IF($A5="","",IF((COUNTIFS(RESULTADOS_GRID!$B:$B,$A5,RESULTADOS_GRID!$AA:$AA,">=0")+COUNTIFS(RESULTADOS_GRID!$B:$B,$A5,RESULTADOS_GRID!$AA:$AA,"<0"))=0,"",SUMIF(RESULTADOS_GRID!$B:$B,$A5,RESULTADOS_GRID!$AA:$AA)/(COUNTIFS(RESULTADOS_GRID!$B:$B,$A5,RESULTADOS_GRID!$AA:$AA,">=0")+COUNTIFS(RESULTADOS_GRID!$B:$B,$A5,RESULTADOS_GRID!$AA:$AA,"<0")))) | M5: =IF($A5="","",IF((COUNTIFS(RESULTADOS_GRID!$B:$B,$A5,RESULTADOS_GRID!$AB:$AB,">=0")+COUNTIFS(RESULTADOS_GRID!$B:$B,$A5,RESULTADOS_GRID!$AB:$AB,"<0"))=0,"",SUMIF(RESULTADOS_GRID!$B:$B,$A5,RESULTADOS_GRID!$AB:$AB)/(COUNTIFS(RESULTADOS_GRID!$B:$B,$A5,RESULTADOS_GRID!$AB:$AB,">=0")+COUNTIFS(RESULTADOS_GRID!$B:$B,$A5,RESULTADOS_GRID!$AB:$AB,"<0")))) | O5: =IF($I5="","",COUNTIFS($I$2:$I$101,"<"&$I5)+1)
A6: E5_v1 | B6: =IF($A6="","",IFERROR(INDEX(RESULTADOS_GRID!$C:$C,MATCH($A6,RESULTADOS_GRID!$B:$B,0)),"")) | C6: =IF($A6="","",IFERROR(INDEX(RESULTADOS_GRID!$E:$E,MATCH($A6,RESULTADOS_GRID!$B:$B,0)),"")) | D6: =IF($A6="","",IFERROR(INDEX(RESULTADOS_GRID!$D:$D,MATCH($A6,RESULTADOS_GRID!$B:$B,0)),"")) | E6: =IF($A6="","",COUNTIF(RESULTADOS_GRID!$B:$B,$A6)) | F6: =IF($A6="","",SUMIF(RESULTADOS_GRID!$B:$B,$A6,RESULTADOS_GRID!$X:$X)) | H6: =CONFIG_REFERENCIA!$E$7 | I6: =IF($A6="","",$F6+N($G6)*$H6) | J6: =IF($A6="","",IF((COUNTIFS(RESULTADOS_GRID!$B:$B,$A6,RESULTADOS_GRID!$Y:$Y,">=0")+COUNTIFS(RESULTADOS_GRID!$B:$B,$A6,RESULTADOS_GRID!$Y:$Y,"<0"))=0,"",SUMIF(RESULTADOS_GRID!$B:$B,$A6,RESULTADOS_GRID!$Y:$Y)/(COUNTIFS(RESULTADOS_GRID!$B:$B,$A6,RESULTADOS_GRID!$Y:$Y,">=0")+COUNTIFS(RESULTADOS_GRID!$B:$B,$A6,RESULTADOS_GRID!$Y:$Y,"<0")))) | K6: =IF($A6="","",IF((COUNTIFS(RESULTADOS_GRID!$B:$B,$A6,RESULTADOS_GRID!$Z:$Z,">=0")+COUNTIFS(RESULTADOS_GRID!$B:$B,$A6,RESULTADOS_GRID!$Z:$Z,"<0"))=0,"",SUMIF(RESULTADOS_GRID!$B:$B,$A6,RESULTADOS_GRID!$Z:$Z)/(COUNTIFS(RESULTADOS_GRID!$B:$B,$A6,RESULTADOS_GRID!$Z:$Z,">=0")+COUNTIFS(RESULTADOS_GRID!$B:$B,$A6,RESULTADOS_GRID!$Z:$Z,"<0")))) | L6: =IF($A6="","",IF((COUNTIFS(RESULTADOS_GRID!$B:$B,$A6,RESULTADOS_GRID!$AA:$AA,">=0")+COUNTIFS(RESULTADOS_GRID!$B:$B,$A6,RESULTADOS_GRID!$AA:$AA,"<0"))=0,"",SUMIF(RESULTADOS_GRID!$B:$B,$A6,RESULTADOS_GRID!$AA:$AA)/(COUNTIFS(RESULTADOS_GRID!$B:$B,$A6,RESULTADOS_GRID!$AA:$AA,">=0")+COUNTIFS(RESULTADOS_GRID!$B:$B,$A6,RESULTADOS_GRID!$AA:$AA,"<0")))) | M6: =IF($A6="","",IF((COUNTIFS(RESULTADOS_GRID!$B:$B,$A6,RESULTADOS_GRID!$AB:$AB,">=0")+COUNTIFS(RESULTADOS_GRID!$B:$B,$A6,RESULTADOS_GRID!$AB:$AB,"<0"))=0,"",SUMIF(RESULTADOS_GRID!$B:$B,$A6,RESULTADOS_GRID!$AB:$AB)/(COUNTIFS(RESULTADOS_GRID!$B:$B,$A6,RESULTADOS_GRID!$AB:$AB,">=0")+COUNTIFS(RESULTADOS_GRID!$B:$B,$A6,RESULTADOS_GRID!$AB:$AB,"<0")))) | O6: =IF($I6="","",COUNTIFS($I$2:$I$101,"<"&$I6)+1)
A7: E6_v1 | B7: =IF($A7="","",IFERROR(INDEX(RESULTADOS_GRID!$C:$C,MATCH($A7,RESULTADOS_GRID!$B:$B,0)),"")) | C7: =IF($A7="","",IFERROR(INDEX(RESULTADOS_GRID!$E:$E,MATCH($A7,RESULTADOS_GRID!$B:$B,0)),"")) | D7: =IF($A7="","",IFERROR(INDEX(RESULTADOS_GRID!$D:$D,MATCH($A7,RESULTADOS_GRID!$B:$B,0)),"")) | E7: =IF($A7="","",COUNTIF(RESULTADOS_GRID!$B:$B,$A7)) | F7: =IF($A7="","",SUMIF(RESULTADOS_GRID!$B:$B,$A7,RESULTADOS_GRID!$X:$X)) | H7: =CONFIG_REFERENCIA!$E$7 | I7: =IF($A7="","",$F7+N($G7)*$H7) | J7: =IF($A7="","",IF((COUNTIFS(RESULTADOS_GRID!$B:$B,$A7,RESULTADOS_GRID!$Y:$Y,">=0")+COUNTIFS(RESULTADOS_GRID!$B:$B,$A7,RESULTADOS_GRID!$Y:$Y,"<0"))=0,"",SUMIF(RESULTADOS_GRID!$B:$B,$A7,RESULTADOS_GRID!$Y:$Y)/(COUNTIFS(RESULTADOS_GRID!$B:$B,$A7,RESULTADOS_GRID!$Y:$Y,">=0")+COUNTIFS(RESULTADOS_GRID!$B:$B,$A7,RESULTADOS_GRID!$Y:$Y,"<0")))) | K7: =IF($A7="","",IF((COUNTIFS(RESULTADOS_GRID!$B:$B,$A7,RESULTADOS_GRID!$Z:$Z,">=0")+COUNTIFS(RESULTADOS_GRID!$B:$B,$A7,RESULTADOS_GRID!$Z:$Z,"<0"))=0,"",SUMIF(RESULTADOS_GRID!$B:$B,$A7,RESULTADOS_GRID!$Z:$Z)/(COUNTIFS(RESULTADOS_GRID!$B:$B,$A7,RESULTADOS_GRID!$Z:$Z,">=0")+COUNTIFS(RESULTADOS_GRID!$B:$B,$A7,RESULTADOS_GRID!$Z:$Z,"<0")))) | L7: =IF($A7="","",IF((COUNTIFS(RESULTADOS_GRID!$B:$B,$A7,RESULTADOS_GRID!$AA:$AA,">=0")+COUNTIFS(RESULTADOS_GRID!$B:$B,$A7,RESULTADOS_GRID!$AA:$AA,"<0"))=0,"",SUMIF(RESULTADOS_GRID!$B:$B,$A7,RESULTADOS_GRID!$AA:$AA)/(COUNTIFS(RESULTADOS_GRID!$B:$B,$A7,RESULTADOS_GRID!$AA:$AA,">=0")+COUNTIFS(RESULTADOS_GRID!$B:$B,$A7,RESULTADOS_GRID!$AA:$AA,"<0")))) | M7: =IF($A7="","",IF((COUNTIFS(RESULTADOS_GRID!$B:$B,$A7,RESULTADOS_GRID!$AB:$AB,">=0")+COUNTIFS(RESULTADOS_GRID!$B:$B,$A7,RESULTADOS_GRID!$AB:$AB,"<0"))=0,"",SUMIF(RESULTADOS_GRID!$B:$B,$A7,RESULTADOS_GRID!$AB:$AB)/(COUNTIFS(RESULTADOS_GRID!$B:$B,$A7,RESULTADOS_GRID!$AB:$AB,">=0")+COUNTIFS(RESULTADOS_GRID!$B:$B,$A7,RESULTADOS_GRID!$AB:$AB,"<0")))) | O7: =IF($I7="","",COUNTIFS($I$2:$I$101,"<"&$I7)+1)
A8: E7_v1 | B8: =IF($A8="","",IFERROR(INDEX(RESULTADOS_GRID!$C:$C,MATCH($A8,RESULTADOS_GRID!$B:$B,0)),"")) | C8: =IF($A8="","",IFERROR(INDEX(RESULTADOS_GRID!$E:$E,MATCH($A8,RESULTADOS_GRID!$B:$B,0)),"")) | D8: =IF($A8="","",IFERROR(INDEX(RESULTADOS_GRID!$D:$D,MATCH($A8,RESULTADOS_GRID!$B:$B,0)),"")) | E8: =IF($A8="","",COUNTIF(RESULTADOS_GRID!$B:$B,$A8)) | F8: =IF($A8="","",SUMIF(RESULTADOS_GRID!$B:$B,$A8,RESULTADOS_GRID!$X:$X)) | H8: =CONFIG_REFERENCIA!$E$7 | I8: =IF($A8="","",$F8+N($G8)*$H8) | J8: =IF($A8="","",IF((COUNTIFS(RESULTADOS_GRID!$B:$B,$A8,RESULTADOS_GRID!$Y:$Y,">=0")+COUNTIFS(RESULTADOS_GRID!$B:$B,$A8,RESULTADOS_GRID!$Y:$Y,"<0"))=0,"",SUMIF(RESULTADOS_GRID!$B:$B,$A8,RESULTADOS_GRID!$Y:$Y)/(COUNTIFS(RESULTADOS_GRID!$B:$B,$A8,RESULTADOS_GRID!$Y:$Y,">=0")+COUNTIFS(RESULTADOS_GRID!$B:$B,$A8,RESULTADOS_GRID!$Y:$Y,"<0")))) | K8: =IF($A8="","",IF((COUNTIFS(RESULTADOS_GRID!$B:$B,$A8,RESULTADOS_GRID!$Z:$Z,">=0")+COUNTIFS(RESULTADOS_GRID!$B:$B,$A8,RESULTADOS_GRID!$Z:$Z,"<0"))=0,"",SUMIF(RESULTADOS_GRID!$B:$B,$A8,RESULTADOS_GRID!$Z:$Z)/(COUNTIFS(RESULTADOS_GRID!$B:$B,$A8,RESULTADOS_GRID!$Z:$Z,">=0")+COUNTIFS(RESULTADOS_GRID!$B:$B,$A8,RESULTADOS_GRID!$Z:$Z,"<0")))) | L8: =IF($A8="","",IF((COUNTIFS(RESULTADOS_GRID!$B:$B,$A8,RESULTADOS_GRID!$AA:$AA,">=0")+COUNTIFS(RESULTADOS_GRID!$B:$B,$A8,RESULTADOS_GRID!$AA:$AA,"<0"))=0,"",SUMIF(RESULTADOS_GRID!$B:$B,$A8,RESULTADOS_GRID!$AA:$AA)/(COUNTIFS(RESULTADOS_GRID!$B:$B,$A8,RESULTADOS_GRID!$AA:$AA,">=0")+COUNTIFS(RESULTADOS_GRID!$B:$B,$A8,RESULTADOS_GRID!$AA:$AA,"<0")))) | M8: =IF($A8="","",IF((COUNTIFS(RESULTADOS_GRID!$B:$B,$A8,RESULTADOS_GRID!$AB:$AB,">=0")+COUNTIFS(RESULTADOS_GRID!$B:$B,$A8,RESULTADOS_GRID!$AB:$AB,"<0"))=0,"",SUMIF(RESULTADOS_GRID!$B:$B,$A8,RESULTADOS_GRID!$AB:$AB)/(COUNTIFS(RESULTADOS_GRID!$B:$B,$A8,RESULTADOS_GRID!$AB:$AB,">=0")+COUNTIFS(RESULTADOS_GRID!$B:$B,$A8,RESULTADOS_GRID!$AB:$AB,"<0")))) | O8: =IF($I8="","",COUNTIFS($I$2:$I$101,"<"&$I8)+1)
A9: E8_v1 | B9: =IF($A9="","",IFERROR(INDEX(RESULTADOS_GRID!$C:$C,MATCH($A9,RESULTADOS_GRID!$B:$B,0)),"")) | C9: =IF($A9="","",IFERROR(INDEX(RESULTADOS_GRID!$E:$E,MATCH($A9,RESULTADOS_GRID!$B:$B,0)),"")) | D9: =IF($A9="","",IFERROR(INDEX(RESULTADOS_GRID!$D:$D,MATCH($A9,RESULTADOS_GRID!$B:$B,0)),"")) | E9: =IF($A9="","",COUNTIF(RESULTADOS_GRID!$B:$B,$A9)) | F9: =IF($A9="","",SUMIF(RESULTADOS_GRID!$B:$B,$A9,RESULTADOS_GRID!$X:$X)) | H9: =CONFIG_REFERENCIA!$E$7 | I9: =IF($A9="","",$F9+N($G9)*$H9) | J9: =IF($A9="","",IF((COUNTIFS(RESULTADOS_GRID!$B:$B,$A9,RESULTADOS_GRID!$Y:$Y,">=0")+COUNTIFS(RESULTADOS_GRID!$B:$B,$A9,RESULTADOS_GRID!$Y:$Y,"<0"))=0,"",SUMIF(RESULTADOS_GRID!$B:$B,$A9,RESULTADOS_GRID!$Y:$Y)/(COUNTIFS(RESULTADOS_GRID!$B:$B,$A9,RESULTADOS_GRID!$Y:$Y,">=0")+COUNTIFS(RESULTADOS_GRID!$B:$B,$A9,RESULTADOS_GRID!$Y:$Y,"<0")))) | K9: =IF($A9="","",IF((COUNTIFS(RESULTADOS_GRID!$B:$B,$A9,RESULTADOS_GRID!$Z:$Z,">=0")+COUNTIFS(RESULTADOS_GRID!$B:$B,$A9,RESULTADOS_GRID!$Z:$Z,"<0"))=0,"",SUMIF(RESULTADOS_GRID!$B:$B,$A9,RESULTADOS_GRID!$Z:$Z)/(COUNTIFS(RESULTADOS_GRID!$B:$B,$A9,RESULTADOS_GRID!$Z:$Z,">=0")+COUNTIFS(RESULTADOS_GRID!$B:$B,$A9,RESULTADOS_GRID!$Z:$Z,"<0")))) | L9: =IF($A9="","",IF((COUNTIFS(RESULTADOS_GRID!$B:$B,$A9,RESULTADOS_GRID!$AA:$AA,">=0")+COUNTIFS(RESULTADOS_GRID!$B:$B,$A9,RESULTADOS_GRID!$AA:$AA,"<0"))=0,"",SUMIF(RESULTADOS_GRID!$B:$B,$A9,RESULTADOS_GRID!$AA:$AA)/(COUNTIFS(RESULTADOS_GRID!$B:$B,$A9,RESULTADOS_GRID!$AA:$AA,">=0")+COUNTIFS(RESULTADOS_GRID!$B:$B,$A9,RESULTADOS_GRID!$AA:$AA,"<0")))) | M9: =IF($A9="","",IF((COUNTIFS(RESULTADOS_GRID!$B:$B,$A9,RESULTADOS_GRID!$AB:$AB,">=0")+COUNTIFS(RESULTADOS_GRID!$B:$B,$A9,RESULTADOS_GRID!$AB:$AB,"<0"))=0,"",SUMIF(RESULTADOS_GRID!$B:$B,$A9,RESULTADOS_GRID!$AB:$AB)/(COUNTIFS(RESULTADOS_GRID!$B:$B,$A9,RESULTADOS_GRID!$AB:$AB,">=0")+COUNTIFS(RESULTADOS_GRID!$B:$B,$A9,RESULTADOS_GRID!$AB:$AB,"<0")))) | O9: =IF($I9="","",COUNTIFS($I$2:$I$101,"<"&$I9)+1)
A10: E9_v1 | B10: =IF($A10="","",IFERROR(INDEX(RESULTADOS_GRID!$C:$C,MATCH($A10,RESULTADOS_GRID!$B:$B,0)),"")) | C10: =IF($A10="","",IFERROR(INDEX(RESULTADOS_GRID!$E:$E,MATCH($A10,RESULTADOS_GRID!$B:$B,0)),"")) | D10: =IF($A10="","",IFERROR(INDEX(RESULTADOS_GRID!$D:$D,MATCH($A10,RESULTADOS_GRID!$B:$B,0)),"")) | E10: =IF($A10="","",COUNTIF(RESULTADOS_GRID!$B:$B,$A10)) | F10: =IF($A10="","",SUMIF(RESULTADOS_GRID!$B:$B,$A10,RESULTADOS_GRID!$X:$X)) | H10: =CONFIG_REFERENCIA!$E$7 | I10: =IF($A10="","",$F10+N($G10)*$H10) | J10: =IF($A10="","",IF((COUNTIFS(RESULTADOS_GRID!$B:$B,$A10,RESULTADOS_GRID!$Y:$Y,">=0")+COUNTIFS(RESULTADOS_GRID!$B:$B,$A10,RESULTADOS_GRID!$Y:$Y,"<0"))=0,"",SUMIF(RESULTADOS_GRID!$B:$B,$A10,RESULTADOS_GRID!$Y:$Y)/(COUNTIFS(RESULTADOS_GRID!$B:$B,$A10,RESULTADOS_GRID!$Y:$Y,">=0")+COUNTIFS(RESULTADOS_GRID!$B:$B,$A10,RESULTADOS_GRID!$Y:$Y,"<0")))) | K10: =IF($A10="","",IF((COUNTIFS(RESULTADOS_GRID!$B:$B,$A10,RESULTADOS_GRID!$Z:$Z,">=0")+COUNTIFS(RESULTADOS_GRID!$B:$B,$A10,RESULTADOS_GRID!$Z:$Z,"<0"))=0,"",SUMIF(RESULTADOS_GRID!$B:$B,$A10,RESULTADOS_GRID!$Z:$Z)/(COUNTIFS(RESULTADOS_GRID!$B:$B,$A10,RESULTADOS_GRID!$Z:$Z,">=0")+COUNTIFS(RESULTADOS_GRID!$B:$B,$A10,RESULTADOS_GRID!$Z:$Z,"<0")))) | L10: =IF($A10="","",IF((COUNTIFS(RESULTADOS_GRID!$B:$B,$A10,RESULTADOS_GRID!$AA:$AA,">=0")+COUNTIFS(RESULTADOS_GRID!$B:$B,$A10,RESULTADOS_GRID!$AA:$AA,"<0"))=0,"",SUMIF(RESULTADOS_GRID!$B:$B,$A10,RESULTADOS_GRID!$AA:$AA)/(COUNTIFS(RESULTADOS_GRID!$B:$B,$A10,RESULTADOS_GRID!$AA:$AA,">=0")+COUNTIFS(RESULTADOS_GRID!$B:$B,$A10,RESULTADOS_GRID!$AA:$AA,"<0")))) | M10: =IF($A10="","",IF((COUNTIFS(RESULTADOS_GRID!$B:$B,$A10,RESULTADOS_GRID!$AB:$AB,">=0")+COUNTIFS(RESULTADOS_GRID!$B:$B,$A10,RESULTADOS_GRID!$AB:$AB,"<0"))=0,"",SUMIF(RESULTADOS_GRID!$B:$B,$A10,RESULTADOS_GRID!$AB:$AB)/(COUNTIFS(RESULTADOS_GRID!$B:$B,$A10,RESULTADOS_GRID!$AB:$AB,">=0")+COUNTIFS(RESULTADOS_GRID!$B:$B,$A10,RESULTADOS_GRID!$AB:$AB,"<0")))) | O10: =IF($I10="","",COUNTIFS($I$2:$I$101,"<"&$I10)+1)
